package com.raishxn.gtna.common.data.multiblock;

import com.gregtechceu.gtceu.api.pattern.FactoryBlockPattern;

public final class DimensionallyTranscendentPatterns {

    public static final FactoryBlockPattern DTPF = FactoryBlockPattern.start()
            .aisle(" ddd   ddd             ddd   ddd ", "                                 ", "                                 ", "                                 ", " ddd   ddd             ddd   ddd ", "                                 ", "                                 ", "                                 ", "                                 ", "                                 ", " ddd   ddd             ddd   ddd ", "                                 ", "                                 ", "                                 ", " ddd   ddd   d     d   ddd   ddd ", "         d   d     d   d         ", "         d   d     d   d         ", "                                 ", "                                 ", "                                 ", "         d   d     d   d         ", "         d   d     d   d         ", "         d   d     d   d         ", "                                 ")
            .aisle("dbbbd dbbbd    d d    dbbbd dbbbd", " CCC   CCC             CCC   CCC ", " CCC   CCC             CCC   CCC ", " CCC   CCC             CCC   CCC ", "dbbbd dbbbd           dbbbd dbbbd", "  d     d               d     d  ", "  d     d               d     d  ", "                                 ", "  d     d               d     d  ", "  d     d               d     d  ", "dbbbd dbbbd           dbbbd dbbbd", " CCC   CCC             CCC   CCC ", " CCC   CCC             CCC   CCC ", " CCC   CCC   d     d   CCC   CCC ", "dbbbd dbbdCCCb     bCCCdbbd dbbbd", "         bCCCb     bCCCb         ", "         bCCCb     bCCCb         ", "         d   d     d   d         ", "                                 ", "         d   d     d   d         ", "         bCCCb     bCCCb         ", "         bCCCb     bCCCb         ", "         bCCCb     bCCCb         ", "         d   d     d   d         ")
            .aisle("dbbbd dbbbdddddsdsdddddbbbd dbbbd", " CbC   CbC             CbC   CbC ", " CbC   CbC             CbC   CbC ", " CbC   CbC             CbC   CbC ", "dbbbd dbbbd           dbbbd dbbbd", " ddd   ddd             ddd   ddd ", " ddd   ddd             ddd   ddd ", "  s     s               s     s  ", " ddd   ddd             ddd   ddd ", " ddd   ddd             ddd   ddd ", "dbbbd dbbbd           dbbbd dbbbd", " CbC   CbC             CbC   CbC ", " CbC   CbC             CbC   CbC ", " CbC   CbC   d     d   CbC   CbC ", "dbbbd dbbdCCCb     bCCCdbbd dbbbd", "  d     sbbbbbddsddbbbbbs     d  ", "  d      bCCCb     bCCCb      d  ", "  d      d   d     d   d      d  ", "   s                         s   ", "   s     d   d     d   d     s   ", "    ss   bCCCb     bCCCb   ss    ", "      dddbbbbbddsddbbbbbddd      ", "         bCCCb     bCCCb         ", "         d   d     d   d         ")
            .aisle("dbbbdddbbbd    ded    dbbbdddbbbd", " CCCCCCCCC             CCCCCCCCC ", " CCCCCCCCC             CCCCCCCCC ", " CCCCCCCCC             CCCCCCCCC ", "dbbbdddbbbd           dbbbdddbbbd", "  d     d               d     d  ", "  d     d               d     d  ", "                                 ", "  d     d               d     d  ", "  d     d               d     d  ", "dbbbdddbbbd           dbbbdddbbbd", " CCCCCCCCC             CCCCCCCCC ", " CCCCCCCCC             CCCCCCCCC ", " CCCCCCCCC   d     d   CCCCCCCCC ", "dbbbdddbbdCCCb     bCCCdbbdddbbbd", "         bCCCb     bCCCb         ", "         bCCCb     bCCCb         ", "         dCCCd     dCCCd         ", "  s      dCCCd     dCCCd      s  ", "  s      dCCCd     dCCCd      s  ", "         bCCCb     bCCCb         ", "    ss   bCCCb     bCCCb   ss    ", "         bCCCb     bCCCb         ", "         d   d     d   d         ")
            .aisle(" ddd   ddd     ded     ddd   ddd ", "   C   C                 C   C   ", "   C   C                 C   C   ", "   C   C                 C   C   ", " ddd   ddd             ddd   ddd ", "                                 ", "                                 ", "                                 ", "                                 ", "                                 ", " ddd   ddd             ddd   ddd ", "   C   C                 C   C   ", "   C   C                 C   C   ", "   C   C                 C   C   ", " ddd   dd    d     d    dd   ddd ", "         d   d     d   d         ", "         dCCCd     dCCCd         ", "                                 ", "                                 ", "                                 ", "  s      dCCCd     dCCCd      s  ", "   s     d   d     d   d     s   ", "         d   d     d   d         ", "                                 ")
            .aisle("   d   d       ded       d   d   ", "   C   C                 C   C   ", "   C   C                 C   C   ", "   C   C                 C   C   ", "   d   d                 d   d   ", "                                 ", "                                 ", "                                 ", "                                 ", "                                 ", "   d   d                 d   d   ", "   C   C                 C   C   ", "   C   C                 C   C   ", "   C   C                 C   C   ", "   d   d                 d   d   ", "                                 ", "         dCCCd     dCCCd         ", "                                 ", "                                 ", "                                 ", "  s      dCCCd     dCCCd      s  ", "   s                         s   ", "                                 ", "                                 ")
            .aisle(" ddd   ddd     ded     ddd   ddd ", "   C   C                 C   C   ", "   C   C                 C   C   ", "   C   C                 C   C   ", " ddd   ddd             ddd   ddd ", "                                 ", "                                 ", "                                 ", "                                 ", "                                 ", " ddd   ddd             ddd   ddd ", "   C   C                 C   C   ", "   C   C                 C   C   ", "   C   C                 C   C   ", " ddd   dd    d     d    dd   ddd ", "         d   d     d   d         ", "         dCCCd     dCCCd         ", "                                 ", "                                 ", "                                 ", "         dCCCd     dCCCd         ", "  d      d   d     d   d      d  ", "         d   d     d   d         ", "                                 ")
            .aisle("dbbbdddbbbd    ded    dbbbdddbbbd", " CCCCCCCCC             CCCCCCCCC ", " CCCCCCCCC             CCCCCCCCC ", " CCCCCCCCC             CCCCCCCCC ", "dbbbdddbbbd           dbbbdddbbbd", "  d     d               d     d  ", "  d     d               d     d  ", "                                 ", "  d     d               d     d  ", "  d     d               d     d  ", "dbbbdddbbbd           dbbbdddbbbd", " CCCCCCCCC             CCCCCCCCC ", " CCCCCCCCC             CCCCCCCCC ", " CCCCCCCCC   d     d   CCCCCCCCC ", "dbbbdddbbdCCCb     bCCCdbbdddbbbd", "         bCCCb     bCCCb         ", "         bCCCb     bCCCb         ", "         dCCCd     dCCCd         ", "         dCCCd     dCCCd         ", "         dCCCd     dCCCd         ", "         bCCCb     bCCCb         ", "  d      bCCCb     bCCCb      d  ", "         bCCCb     bCCCb         ", "         d   d     d   d         ")
            .aisle("dbbbd dbbbdddddsdsdddddbbbd dbbbd", " CbC   CbC             CbC   CbC ", " CbC   CbC             CbC   CbC ", " CbC   CbC             CbC   CbC ", "dbbbd dbbbd           dbbbd dbbbd", " ddd   ddd             ddd   ddd ", " ddd   ddd             ddd   ddd ", "  s     s               s     s  ", " ddd   ddd             ddd   ddd ", " ddd   ddd             ddd   ddd ", "dbbbd dbbbd           dbbbd dbbbd", " CbC   CbC             CbC   CbC ", " CbC   CbC             CbC   CbC ", " CbC   CbC   d     d   CbC   CbC ", "dbbbd dbbdCCCb     bCCCdbbd dbbbd", "  s     sbbbbbddsddbbbbbs     s  ", "         bCCCb     bCCCb         ", "         d   d     d   d         ", "                                 ", "         d   d     d   d         ", "         bCCCb     bCCCb         ", "  d     sbbbbbddsddbbbbbs     d  ", "         bCCCb     bCCCb         ", "         d   d     d   d         ")
            .aisle("dbbbd dbbbd    ded    dbbbd dbbbd", " CCC   CCC             CCC   CCC ", " CCC   CCC             CCC   CCC ", " CCC   CCC             CCC   CCC ", "dbbbd dbbbd           dbbbd dbbbd", "  d     d               d     d  ", "  d     d               d     d  ", "                                 ", "  d     d               d     d  ", "  d     d               d     d  ", "dbbbd dbbbd           dbbbd dbbbd", " CCC   CCC             CCC   CCC ", " CCC   CCC             CCC   CCC ", " CCC   CCC   d     d   CCC   CCC ", "dddd   dddCCCb     bCCCddd   dddd", "dbbbd dbbdCCCb     bCCCdbbd dbbbd", "dbbbdddbbdCCCb     bCCCdbbdddbbbd", " ddd   ddd   d     d   ddd   ddd ", "   d   d                 d   d   ", " ddd   ddd   d     d   ddd   ddd ", "dbbbdddbbdCCCb     bCCCdbbdddbbbd", "dbbbd dbbdCCCb     bCCCdbbd dbbbd", "dbbbd dbbdCCCb     bCCCdbbd dbbbd", " ddd   ddd   d     d   ddd   ddd ")
            .aisle(" ddd   ddd     ded     ddd   ddd ", "                                 ", "                                 ", "                                 ", " ddd   ddd             ddd   ddd ", "                                 ", "                                 ", "                                 ", "                                 ", "                                 ", " ddd   ddd             ddd   ddd ", "                                 ", "                                 ", "                                 ", " CCC   CCC   d     d   CCC   CCC ", " CbC   CbC   d     d   CbC   CbC ", " CCCCCCCCC   d     d   CCCCCCCCC ", "   C   C                 C   C   ", "   C   C                 C   C   ", "   C   C                 C   C   ", " CCCCCCCCC   d     d   CCCCCCCCC ", " CbC   CbC   d     d   CbC   CbC ", " CCC   CCC   d     d   CCC   CCC ", "                                 ")
            .aisle("  d     d      ded      d     d  ", "                                 ", "                                 ", "                                 ", "                                 ", "                                 ", "                                 ", "                                 ", "                                 ", "                                 ", "                                 ", "                                 ", "                                 ", "                                 ", " CCC   CCC             CCC   CCC ", " CbC   CbC             CbC   CbC ", " CCCCCCCCC             CCCCCCCCC ", "   C   C                 C   C   ", "   C   C                 C   C   ", "   C   C                 C   C   ", " CCCCCCCCC             CCCCCCCCC ", " CbC   CbC             CbC   CbC ", " CCC   CCC             CCC   CCC ", "                                 ")
            .aisle("  d     d      ded      d     d  ", "                                 ", "                                 ", "                                 ", "                                 ", "                                 ", "                                 ", "                                 ", "                                 ", "                                 ", "                                 ", "                                 ", "                                 ", "                                 ", " CCC   CCC             CCC   CCC ", " CbC   CbC             CbC   CbC ", " CCCCCCCCC             CCCCCCCCC ", "   C   C                 C   C   ", "   C   C                 C   C   ", "   C   C                 C   C   ", " CCCCCCCCC             CCCCCCCCC ", " CbC   CbC             CbC   CbC ", " CCC   CCC             CCC   CCC ", "                                 ")
            .aisle("  d     d     dsdsd     d     d  ", "                                 ", "                                 ", "                                 ", "                                 ", "                                 ", "                                 ", "                                 ", "                                 ", "                                 ", "                                 ", "                                 ", "                                 ", " ddd   ddd             ddd   ddd ", "dbbbd dbbbd           dbbbd dbbbd", "dbbbd dbbbd           dbbbd dbbbd", "dbbbdddbbbd           dbbbdddbbbd", " ddd   ddd             ddd   ddd ", "   d   d                 d   d   ", " ddd   ddd             ddd   ddd ", "dbbbdddbbbd           dbbbdddbbbd", "dbbbd dbbbd           dbbbd dbbbd", "dbbbd dbbbd           dbbbd dbbbd", " ddd   ddd             ddd   ddd ")
            .aisle("  d     d    deeeeed    d     d  ", "                                 ", "                                 ", "                                 ", "                                 ", "                                 ", "                                 ", "                                 ", "                                 ", "                                 ", "                                 ", "                                 ", "                                 ", "                                 ", "                                 ", "  d     d               d     d  ", "                                 ", "                                 ", "                                 ", "                                 ", "                                 ", "  d     d               d     d  ", "                                 ", "                                 ")
            .aisle(" dsdddddsddddseedeesddddsdddddsd ", "                d                ", "                                 ", "                                 ", "                                 ", "                                 ", "                                 ", "                                 ", "                                 ", "                                 ", "                                 ", "                                 ", "                                 ", "                                 ", "                                 ", "  d     d               d     d  ", "                                 ", "                                 ", "                                 ", "                                 ", "                                 ", "  d     d               d     d  ", "                                 ", "                                 ")
            .aisle("  deeeeedeeeededddedeeeedeeeeed  ", "               ddd               ", "                a                ", "                                 ", "                                 ", "                                 ", "                                 ", "                                 ", "                                 ", "                                 ", "                                 ", "                                 ", "                                 ", "                                 ", "                                 ", "  s     s               s     s  ", "                                 ", "                                 ", "                                 ", "                                 ", "                                 ", "  s     s               s     s  ", "                                 ", "                                 ")
            .aisle(" dsdddddsddddseedeesddddsdddddsd ", "                d                ", "                                 ", "                                 ", "                                 ", "                                 ", "                                 ", "                                 ", "                                 ", "                                 ", "                                 ", "                                 ", "                                 ", "                                 ", "                                 ", "  d     d               d     d  ", "                                 ", "                                 ", "                                 ", "                                 ", "                                 ", "  d     d               d     d  ", "                                 ", "                                 ")
            .aisle("  d     d    deeeeed    d     d  ", "                                 ", "                                 ", "                                 ", "                                 ", "                                 ", "                                 ", "                                 ", "                                 ", "                                 ", "                                 ", "                                 ", "                                 ", "                                 ", "                                 ", "  d     d               d     d  ", "                                 ", "                                 ", "                                 ", "                                 ", "                                 ", "  d     d               d     d  ", "                                 ", "                                 ")
            .aisle("  d     d     dsdsd     d     d  ", "                                 ", "                                 ", "                                 ", "                                 ", "                                 ", "                                 ", "                                 ", "                                 ", "                                 ", "                                 ", "                                 ", "                                 ", " ddd   ddd             ddd   ddd ", "dbbbd dbbbd           dbbbd dbbbd", "dbbbd dbbbd           dbbbd dbbbd", "dbbbdddbbbd           dbbbdddbbbd", " ddd   ddd             ddd   ddd ", "   d   d                 d   d   ", " ddd   ddd             ddd   ddd ", "dbbbdddbbbd           dbbbdddbbbd", "dbbbd dbbbd           dbbbd dbbbd", "dbbbd dbbbd           dbbbd dbbbd", " ddd   ddd             ddd   ddd ")
            .aisle("  d     d      ded      d     d  ", "                                 ", "                                 ", "                                 ", "                                 ", "                                 ", "                                 ", "                                 ", "                                 ", "                                 ", "                                 ", "                                 ", "                                 ", "                                 ", " CCC   CCC             CCC   CCC ", " CbC   CbC             CbC   CbC ", " CCCCCCCCC             CCCCCCCCC ", "   C   C                 C   C   ", "   C   C                 C   C   ", "   C   C                 C   C   ", " CCCCCCCCC             CCCCCCCCC ", " CbC   CbC             CbC   CbC ", " CCC   CCC             CCC   CCC ", "                                 ")
            .aisle("  d     d      ded      d     d  ", "                                 ", "                                 ", "                                 ", "                                 ", "                                 ", "                                 ", "                                 ", "                                 ", "                                 ", "                                 ", "                                 ", "                                 ", "                                 ", " CCC   CCC             CCC   CCC ", " CbC   CbC             CbC   CbC ", " CCCCCCCCC             CCCCCCCCC ", "   C   C                 C   C   ", "   C   C                 C   C   ", "   C   C                 C   C   ", " CCCCCCCCC             CCCCCCCCC ", " CbC   CbC             CbC   CbC ", " CCC   CCC             CCC   CCC ", "                                 ")
            .aisle(" ddd   ddd     ded     ddd   ddd ", "                                 ", "                                 ", "                                 ", " ddd   ddd             ddd   ddd ", "                                 ", "                                 ", "                                 ", "                                 ", "                                 ", " ddd   ddd             ddd   ddd ", "                                 ", "                                 ", "                                 ", " CCC   CCC   d     d   CCC   CCC ", " CbC   CbC   d     d   CbC   CbC ", " CCCCCCCCC   d     d   CCCCCCCCC ", "   C   C                 C   C   ", "   C   C                 C   C   ", "   C   C                 C   C   ", " CCCCCCCCC   d     d   CCCCCCCCC ", " CbC   CbC   d     d   CbC   CbC ", " CCC   CCC   d     d   CCC   CCC ", "                                 ")
            .aisle("dbbbd dbbbd    ded    dbbbd dbbbd", " CCC   CCC             CCC   CCC ", " CCC   CCC             CCC   CCC ", " CCC   CCC             CCC   CCC ", "dbbbd dbbbd           dbbbd dbbbd", "  d     d               d     d  ", "  d     d               d     d  ", "                                 ", "  d     d               d     d  ", "  d     d               d     d  ", "dbbbd dbbbd           dbbbd dbbbd", " CCC   CCC             CCC   CCC ", " CCC   CCC             CCC   CCC ", " CCC   CCC   d     d   CCC   CCC ", "dddd   dddCCCb     bCCCddd   dddd", "dbbbd dbbdCCCb     bCCCdbbd dbbbd", "dbbbdddbbdCCCb     bCCCdbbdddbbbd", " ddd   ddd   d     d   ddd   ddd ", "   d   d                 d   d   ", " ddd   ddd   d     d   ddd   ddd ", "dbbbdddbbdCCCb     bCCCdbbdddbbbd", "dbbbd dbbdCCCb     bCCCdbbd dbbbd", "dbbbd dbbdCCCb     bCCCdbbd dbbbd", " ddd   ddd   d     d   ddd   ddd ")
            .aisle("dbbbd dbbbdddddsdsdddddbbbd dbbbd", " CbC   CbC             CbC   CbC ", " CbC   CbC             CbC   CbC ", " CbC   CbC             CbC   CbC ", "dbbbd dbbbd           dbbbd dbbbd", " ddd   ddd             ddd   ddd ", " ddd   ddd             ddd   ddd ", "  s     s               s     s  ", " ddd   ddd             ddd   ddd ", " ddd   ddd             ddd   ddd ", "dbbbd dbbbd           dbbbd dbbbd", " CbC   CbC             CbC   CbC ", " CbC   CbC             CbC   CbC ", " CbC   CbC   d     d   CbC   CbC ", "dbbbd dbbdCCCb     bCCCdbbd dbbbd", "  d     sbbbbbddsddbbbbbs     d  ", "  d      bCCCb     bCCCb      d  ", "  d      d   d     d   d      d  ", "   s                         s   ", "   s     d   d     d   d     s   ", "    ss   bCCCb     bCCCb   ss    ", "      dddbbbbbddsddbbbbbddd      ", "         bCCCb     bCCCb         ", "         d   d     d   d         ")
            .aisle("dbbbd dbbbd    d d    dbbbd dbbbd", " CCC   CCC             CCC   CCC ", " CCC   CCC             CCC   CCC ", " CCC   CCC             CCC   CCC ", "dbbbd dbbbd           dbbbd dbbbd", "  d     d               d     d  ", "  d     d               d     d  ", "                                 ", "  d     d               d     d  ", "  d     d               d     d  ", "dbbbd dbbbd           dbbbd dbbbd", " CCC   CCC             CCC   CCC ", " CCC   CCC             CCC   CCC ", " CCC   CCC   d     d   CCC   CCC ", "dbbbd dbbdCCCb     bCCCdbbd dbbbd", "         bCCCb     bCCCb         ", "         bCCCb     bCCCb         ", "         d   d     d   d         ", "                                 ", "         d   d     d   d         ", "         bCCCb     bCCCb         ", "         bCCCb     bCCCb         ", "         bCCCb     bCCCb         ", "         d   d     d   d         ")
            .aisle(" ddd   ddd             ddd   ddd ", "                                 ", "                                 ", "                                 ", " ddd   ddd             ddd   ddd ", "                                 ", "                                 ", "                                 ", "                                 ", "                                 ", " ddd   ddd             ddd   ddd ", "                                 ", "                                 ", "                                 ", " ddd   ddd   d     d   ddd   ddd ", "         d   d     d   d         ", "         d   d     d   d         ", "                                 ", "                                 ", "                                 ", "         d   d     d   d         ", "         d   d     d   d         ", "         d   d     d   d         ", "                                 ");

    private DimensionallyTranscendentPatterns() {}
}
